Traceback (most recent call last):
  File "/usr/local/lib/python3.10/dist-packages/jupyter_cache/executors/utils.py", line 58, in single_nb_execution
    executenb(
  File "/usr/local/lib/python3.10/dist-packages/nbclient/client.py", line 1314, in execute
    return NotebookClient(nb=nb, resources=resources, km=km, **kwargs).execute()
  File "/usr/local/lib/python3.10/dist-packages/jupyter_core/utils/__init__.py", line 165, in wrapped
    return loop.run_until_complete(inner)
  File "/usr/lib/python3.10/asyncio/base_events.py", line 649, in run_until_complete
    return future.result()
  File "/usr/local/lib/python3.10/dist-packages/nbclient/client.py", line 709, in async_execute
    await self.async_execute_cell(
  File "/usr/local/lib/python3.10/dist-packages/nbclient/client.py", line 1062, in async_execute_cell
    await self._check_raise_for_error(cell, cell_index, exec_reply)
  File "/usr/local/lib/python3.10/dist-packages/nbclient/client.py", line 918, in _check_raise_for_error
    raise CellExecutionError.from_cell_and_msg(cell, exec_reply_content)
nbclient.exceptions.CellExecutionError: An error occurred while executing the following cell:
------------------
sns.FacetGrid(iris,hue="Class",size=3).map(sns.distplot,"petal-length").add_legend()
sns.FacetGrid(iris,hue="Class",size=3).map(sns.distplot,"petal-width").add_legend()
sns.FacetGrid(iris,hue="Class",size=3).map(sns.distplot,"sepal-length").add_legend()
plt.show()
------------------


[0;31m---------------------------------------------------------------------------[0m
[0;31mTypeError[0m                                 Traceback (most recent call last)
[0;32m<ipython-input-25-8089baea0bae>[0m in [0;36m<cell line: 1>[0;34m()[0m
[0;32m----> 1[0;31m [0msns[0m[0;34m.[0m[0mFacetGrid[0m[0;34m([0m[0miris[0m[0;34m,[0m[0mhue[0m[0;34m=[0m[0;34m"Class"[0m[0;34m,[0m[0msize[0m[0;34m=[0m[0;36m3[0m[0;34m)[0m[0;34m.[0m[0mmap[0m[0;34m([0m[0msns[0m[0;34m.[0m[0mdistplot[0m[0;34m,[0m[0;34m"petal-length"[0m[0;34m)[0m[0;34m.[0m[0madd_legend[0m[0;34m([0m[0;34m)[0m[0;34m[0m[0;34m[0m[0m
[0m[1;32m      2[0m [0msns[0m[0;34m.[0m[0mFacetGrid[0m[0;34m([0m[0miris[0m[0;34m,[0m[0mhue[0m[0;34m=[0m[0;34m"Class"[0m[0;34m,[0m[0msize[0m[0;34m=[0m[0;36m3[0m[0;34m)[0m[0;34m.[0m[0mmap[0m[0;34m([0m[0msns[0m[0;34m.[0m[0mdistplot[0m[0;34m,[0m[0;34m"petal-width"[0m[0;34m)[0m[0;34m.[0m[0madd_legend[0m[0;34m([0m[0;34m)[0m[0;34m[0m[0;34m[0m[0m
[1;32m      3[0m [0msns[0m[0;34m.[0m[0mFacetGrid[0m[0;34m([0m[0miris[0m[0;34m,[0m[0mhue[0m[0;34m=[0m[0;34m"Class"[0m[0;34m,[0m[0msize[0m[0;34m=[0m[0;36m3[0m[0;34m)[0m[0;34m.[0m[0mmap[0m[0;34m([0m[0msns[0m[0;34m.[0m[0mdistplot[0m[0;34m,[0m[0;34m"sepal-length"[0m[0;34m)[0m[0;34m.[0m[0madd_legend[0m[0;34m([0m[0;34m)[0m[0;34m[0m[0;34m[0m[0m
[1;32m      4[0m [0mplt[0m[0;34m.[0m[0mshow[0m[0;34m([0m[0;34m)[0m[0;34m[0m[0;34m[0m[0m

[0;31mTypeError[0m: FacetGrid.__init__() got an unexpected keyword argument 'size'

